Traceback (most recent call last):
  File "/Users/ashley/anaconda3/lib/python3.7/site-packages/jupyter_cache/executors/utils.py", line 56, in single_nb_execution
    record_timing=False,
  File "/Users/ashley/anaconda3/lib/python3.7/site-packages/nbclient/client.py", line 1112, in execute
    return NotebookClient(nb=nb, resources=resources, km=km, **kwargs).execute()
  File "/Users/ashley/anaconda3/lib/python3.7/site-packages/nbclient/util.py", line 74, in wrapped
    return just_run(coro(*args, **kwargs))
  File "/Users/ashley/anaconda3/lib/python3.7/site-packages/nbclient/util.py", line 53, in just_run
    return loop.run_until_complete(coro)
  File "/Users/ashley/anaconda3/lib/python3.7/asyncio/base_events.py", line 584, in run_until_complete
    return future.result()
  File "/Users/ashley/anaconda3/lib/python3.7/site-packages/nbclient/client.py", line 554, in async_execute
    cell, index, execution_count=self.code_cells_executed + 1
  File "/Users/ashley/anaconda3/lib/python3.7/site-packages/nbclient/client.py", line 857, in async_execute_cell
    self._check_raise_for_error(cell, exec_reply)
  File "/Users/ashley/anaconda3/lib/python3.7/site-packages/nbclient/client.py", line 760, in _check_raise_for_error
    raise CellExecutionError.from_cell_and_msg(cell, exec_reply_content)
nbclient.exceptions.CellExecutionError: An error occurred while executing the following cell:
------------------
# Note: This id is different from our experiment container id 
session_id = experiments[0]['id']
data = boc.get_ophys_experiment_data(session_id)

# Take a look at the kind of object data is 
print(data)
------------------

[0;31m---------------------------------------------------------------------------[0m
[0;31mIndexError[0m                                Traceback (most recent call last)
[0;32m<ipython-input-8-65de2d0bec7b>[0m in [0;36m<module>[0;34m[0m
[1;32m      1[0m [0;31m# Note: This id is different from our experiment container id[0m[0;34m[0m[0;34m[0m[0;34m[0m[0m
[0;32m----> 2[0;31m [0msession_id[0m [0;34m=[0m [0mexperiments[0m[0;34m[[0m[0;36m0[0m[0;34m][0m[0;34m[[0m[0;34m'id'[0m[0;34m][0m[0;34m[0m[0;34m[0m[0m
[0m[1;32m      3[0m [0mdata[0m [0;34m=[0m [0mboc[0m[0;34m.[0m[0mget_ophys_experiment_data[0m[0;34m([0m[0msession_id[0m[0;34m)[0m[0;34m[0m[0;34m[0m[0m
[1;32m      4[0m [0;34m[0m[0m
[1;32m      5[0m [0;31m# Take a look at the kind of object data is[0m[0;34m[0m[0;34m[0m[0;34m[0m[0m

[0;31mIndexError[0m: list index out of range
IndexError: list index out of range

