Traceback (most recent call last):
  File "/Users/ashley/anaconda3/lib/python3.7/site-packages/jupyter_cache/executors/utils.py", line 56, in single_nb_execution
    record_timing=False,
  File "/Users/ashley/anaconda3/lib/python3.7/site-packages/nbclient/client.py", line 1112, in execute
    return NotebookClient(nb=nb, resources=resources, km=km, **kwargs).execute()
  File "/Users/ashley/anaconda3/lib/python3.7/site-packages/nbclient/util.py", line 74, in wrapped
    return just_run(coro(*args, **kwargs))
  File "/Users/ashley/anaconda3/lib/python3.7/site-packages/nbclient/util.py", line 53, in just_run
    return loop.run_until_complete(coro)
  File "/Users/ashley/anaconda3/lib/python3.7/asyncio/base_events.py", line 584, in run_until_complete
    return future.result()
  File "/Users/ashley/anaconda3/lib/python3.7/site-packages/nbclient/client.py", line 554, in async_execute
    cell, index, execution_count=self.code_cells_executed + 1
  File "/Users/ashley/anaconda3/lib/python3.7/site-packages/nbclient/client.py", line 857, in async_execute_cell
    self._check_raise_for_error(cell, exec_reply)
  File "/Users/ashley/anaconda3/lib/python3.7/site-packages/nbclient/client.py", line 760, in _check_raise_for_error
    raise CellExecutionError.from_cell_and_msg(cell, exec_reply_content)
nbclient.exceptions.CellExecutionError: An error occurred while executing the following cell:
------------------
# Assign the spike times in this particular session session
all_spike_times = session.spike_times

# Assign a list of unit ids for units in VISp brain area
VISp_unit_ids = list(good_units_df[good_units_df['ecephys_structure_acronym'] == 'VISp'].index)

# Assign spike times of first 4 VISp unit entries 
VISp_spike_times = []
for i in range(4):
    VISp_spike_times.append(all_spike_times[VISp_unit_ids[i]])
    print(f"Spikes found for unit {VISp_unit_ids[i]} : {len(all_spike_times[VISp_unit_ids[i]])}")
    print(all_spike_times[VISp_unit_ids[i]])
------------------

[0;31m---------------------------------------------------------------------------[0m
[0;31mNameError[0m                                 Traceback (most recent call last)
[0;32m<ipython-input-2-2be0e03375f3>[0m in [0;36m<module>[0;34m[0m
[1;32m      3[0m [0;34m[0m[0m
[1;32m      4[0m [0;31m# Assign a list of unit ids for units in VISp brain area[0m[0;34m[0m[0;34m[0m[0;34m[0m[0m
[0;32m----> 5[0;31m [0mVISp_unit_ids[0m [0;34m=[0m [0mlist[0m[0;34m([0m[0mgood_units_df[0m[0;34m[[0m[0mgood_units_df[0m[0;34m[[0m[0;34m'ecephys_structure_acronym'[0m[0;34m][0m [0;34m==[0m [0;34m'VISp'[0m[0;34m][0m[0;34m.[0m[0mindex[0m[0;34m)[0m[0;34m[0m[0;34m[0m[0m
[0m[1;32m      6[0m [0;34m[0m[0m
[1;32m      7[0m [0;31m# Assign spike times of first 4 VISp unit entries[0m[0;34m[0m[0;34m[0m[0;34m[0m[0m

[0;31mNameError[0m: name 'good_units_df' is not defined
NameError: name 'good_units_df' is not defined

