Traceback (most recent call last):
  File "/Users/ashley/anaconda3/lib/python3.7/site-packages/jupyter_cache/executors/utils.py", line 56, in single_nb_execution
    record_timing=False,
  File "/Users/ashley/anaconda3/lib/python3.7/site-packages/nbclient/client.py", line 1112, in execute
    return NotebookClient(nb=nb, resources=resources, km=km, **kwargs).execute()
  File "/Users/ashley/anaconda3/lib/python3.7/site-packages/nbclient/util.py", line 74, in wrapped
    return just_run(coro(*args, **kwargs))
  File "/Users/ashley/anaconda3/lib/python3.7/site-packages/nbclient/util.py", line 53, in just_run
    return loop.run_until_complete(coro)
  File "/Users/ashley/anaconda3/lib/python3.7/asyncio/base_events.py", line 584, in run_until_complete
    return future.result()
  File "/Users/ashley/anaconda3/lib/python3.7/site-packages/nbclient/client.py", line 554, in async_execute
    cell, index, execution_count=self.code_cells_executed + 1
  File "/Users/ashley/anaconda3/lib/python3.7/site-packages/nbclient/client.py", line 857, in async_execute_cell
    self._check_raise_for_error(cell, exec_reply)
  File "/Users/ashley/anaconda3/lib/python3.7/site-packages/nbclient/client.py", line 760, in _check_raise_for_error
    raise CellExecutionError.from_cell_and_msg(cell, exec_reply_content)
nbclient.exceptions.CellExecutionError: An error occurred while executing the following cell:
------------------
# Create an instance of the Brain Observatory cache
boc = BrainObservatoryCache(manifest_file='manifest.json')

# Assign container ID from previous section
exp_container_id = 627823571
stim = ['natural_scenes']

# Get experiments for our container id and stimuli of interest
experiments = boc.get_ophys_experiments(experiment_container_ids = [exp_container_id],
                                     stimuli = stim)

# Assign the experiment id 
experiment_id = experiments[0]['id']
experiment_data = boc.get_ophys_experiment_data(experiment_id)

print('Data acquired.')
------------------

[0;31m---------------------------------------------------------------------------[0m
[0;31mIndexError[0m                                Traceback (most recent call last)
[0;32m<ipython-input-3-721ebef5e10c>[0m in [0;36m<module>[0;34m[0m
[1;32m     11[0m [0;34m[0m[0m
[1;32m     12[0m [0;31m# Assign the experiment id[0m[0;34m[0m[0;34m[0m[0;34m[0m[0m
[0;32m---> 13[0;31m [0mexperiment_id[0m [0;34m=[0m [0mexperiments[0m[0;34m[[0m[0;36m0[0m[0;34m][0m[0;34m[[0m[0;34m'id'[0m[0;34m][0m[0;34m[0m[0;34m[0m[0m
[0m[1;32m     14[0m [0mexperiment_data[0m [0;34m=[0m [0mboc[0m[0;34m.[0m[0mget_ophys_experiment_data[0m[0;34m([0m[0mexperiment_id[0m[0;34m)[0m[0;34m[0m[0;34m[0m[0m
[1;32m     15[0m [0;34m[0m[0m

[0;31mIndexError[0m: list index out of range
IndexError: list index out of range

