Traceback (most recent call last):
  File "/Users/VictorMagdaleno/opt/anaconda3/lib/python3.7/site-packages/jupyter_cache/executors/utils.py", line 56, in single_nb_execution
    record_timing=False,
  File "/Users/VictorMagdaleno/opt/anaconda3/lib/python3.7/site-packages/nbclient/client.py", line 1112, in execute
    return NotebookClient(nb=nb, resources=resources, km=km, **kwargs).execute()
  File "/Users/VictorMagdaleno/opt/anaconda3/lib/python3.7/site-packages/nbclient/util.py", line 74, in wrapped
    return just_run(coro(*args, **kwargs))
  File "/Users/VictorMagdaleno/opt/anaconda3/lib/python3.7/site-packages/nbclient/util.py", line 53, in just_run
    return loop.run_until_complete(coro)
  File "/Users/VictorMagdaleno/opt/anaconda3/lib/python3.7/asyncio/base_events.py", line 583, in run_until_complete
    return future.result()
  File "/Users/VictorMagdaleno/opt/anaconda3/lib/python3.7/site-packages/nbclient/client.py", line 554, in async_execute
    cell, index, execution_count=self.code_cells_executed + 1
  File "/Users/VictorMagdaleno/opt/anaconda3/lib/python3.7/site-packages/nbclient/client.py", line 857, in async_execute_cell
    self._check_raise_for_error(cell, exec_reply)
  File "/Users/VictorMagdaleno/opt/anaconda3/lib/python3.7/site-packages/nbclient/client.py", line 760, in _check_raise_for_error
    raise CellExecutionError.from_cell_and_msg(cell, exec_reply_content)
nbclient.exceptions.CellExecutionError: An error occurred while executing the following cell:
------------------
# Select our pre computed feature that we would like to compare 
pre_computed_feature = 'input_resistance_mohm'

# Plot our figure and provide labels
plt.boxplot([mouse_spiny_df[pre_computed_feature], mouse_aspiny_df[pre_computed_feature]])
plt.ylabel('Input Resistance (mohm)')
plt.xticks([1,2], ['Spiny', 'Aspiny'])
plt.title('Input Resistance of Mouse Spiny vs Aspiny Neuron Dendrite Types')

# Show our plot 
plt.show()
------------------

[0;31m---------------------------------------------------------------------------[0m
[0;31mNameError[0m                                 Traceback (most recent call last)
[0;32m<ipython-input-9-bdf4d54128a5>[0m in [0;36m<module>[0;34m[0m
[1;32m      3[0m [0;34m[0m[0m
[1;32m      4[0m [0;31m# Plot our figure and provide labels[0m[0;34m[0m[0;34m[0m[0;34m[0m[0m
[0;32m----> 5[0;31m [0mplt[0m[0;34m.[0m[0mboxplot[0m[0;34m([0m[0;34m[[0m[0mmouse_spiny_df[0m[0;34m[[0m[0mpre_computed_feature[0m[0;34m][0m[0;34m,[0m [0mmouse_aspiny_df[0m[0;34m[[0m[0mpre_computed_feature[0m[0;34m][0m[0;34m][0m[0;34m)[0m[0;34m[0m[0;34m[0m[0m
[0m[1;32m      6[0m [0mplt[0m[0;34m.[0m[0mylabel[0m[0;34m([0m[0;34m'Input Resistance (mohm)'[0m[0;34m)[0m[0;34m[0m[0;34m[0m[0m
[1;32m      7[0m [0mplt[0m[0;34m.[0m[0mxticks[0m[0;34m([0m[0;34m[[0m[0;36m1[0m[0;34m,[0m[0;36m2[0m[0;34m][0m[0;34m,[0m [0;34m[[0m[0;34m'Spiny'[0m[0;34m,[0m [0;34m'Aspiny'[0m[0;34m][0m[0;34m)[0m[0;34m[0m[0;34m[0m[0m

[0;31mNameError[0m: name 'mouse_spiny_df' is not defined
NameError: name 'mouse_spiny_df' is not defined

