Traceback (most recent call last):
  File "/opt/miniconda3/envs/jb_py311/lib/python3.11/site-packages/jupyter_core/utils/__init__.py", line 154, in wrapped
    asyncio.get_running_loop()
RuntimeError: no running event loop

During handling of the above exception, another exception occurred:

Traceback (most recent call last):
  File "/opt/miniconda3/envs/jb_py311/lib/python3.11/site-packages/jupyter_cache/executors/utils.py", line 58, in single_nb_execution
    executenb(
  File "/opt/miniconda3/envs/jb_py311/lib/python3.11/site-packages/nbclient/client.py", line 1319, in execute
    return NotebookClient(nb=nb, resources=resources, km=km, **kwargs).execute()
           ^^^^^^^^^^^^^^^^^^^^^^^^^^^^^^^^^^^^^^^^^^^^^^^^^^^^^^^^^^^^^^^^^^^^^
  File "/opt/miniconda3/envs/jb_py311/lib/python3.11/site-packages/jupyter_core/utils/__init__.py", line 158, in wrapped
    return loop.run_until_complete(inner)
           ^^^^^^^^^^^^^^^^^^^^^^^^^^^^^^
  File "/opt/miniconda3/envs/jb_py311/lib/python3.11/asyncio/base_events.py", line 654, in run_until_complete
    return future.result()
           ^^^^^^^^^^^^^^^
  File "/opt/miniconda3/envs/jb_py311/lib/python3.11/site-packages/nbclient/client.py", line 709, in async_execute
    await self.async_execute_cell(
  File "/opt/miniconda3/envs/jb_py311/lib/python3.11/site-packages/nbclient/client.py", line 1062, in async_execute_cell
    await self._check_raise_for_error(cell, cell_index, exec_reply)
  File "/opt/miniconda3/envs/jb_py311/lib/python3.11/site-packages/nbclient/client.py", line 918, in _check_raise_for_error
    raise CellExecutionError.from_cell_and_msg(cell, exec_reply_content)
nbclient.exceptions.CellExecutionError: An error occurred while executing the following cell:
------------------
# Define your column name below
column_name = ...

print(full_dataframe[column_name].unique())
------------------


[31m---------------------------------------------------------------------------[39m
[31mKeyError[39m                                  Traceback (most recent call last)
[36mFile [39m[32m/opt/miniconda3/envs/jb_py311/lib/python3.11/site-packages/pandas/core/indexes/base.py:3802[39m, in [36mIndex.get_loc[39m[34m(self, key, method, tolerance)[39m
[32m   3801[39m [38;5;28;01mtry[39;00m:
[32m-> [39m[32m3802[39m     [38;5;28;01mreturn[39;00m [38;5;28;43mself[39;49m[43m.[49m[43m_engine[49m[43m.[49m[43mget_loc[49m[43m([49m[43mcasted_key[49m[43m)[49m
[32m   3803[39m [38;5;28;01mexcept[39;00m [38;5;167;01mKeyError[39;00m [38;5;28;01mas[39;00m err:

[36mFile [39m[32m/opt/miniconda3/envs/jb_py311/lib/python3.11/site-packages/pandas/_libs/index.pyx:138[39m, in [36mpandas._libs.index.IndexEngine.get_loc[39m[34m()[39m

[36mFile [39m[32m/opt/miniconda3/envs/jb_py311/lib/python3.11/site-packages/pandas/_libs/index.pyx:165[39m, in [36mpandas._libs.index.IndexEngine.get_loc[39m[34m()[39m

[36mFile [39m[32mpandas/_libs/hashtable_class_helper.pxi:5745[39m, in [36mpandas._libs.hashtable.PyObjectHashTable.get_item[39m[34m()[39m

[36mFile [39m[32mpandas/_libs/hashtable_class_helper.pxi:5753[39m, in [36mpandas._libs.hashtable.PyObjectHashTable.get_item[39m[34m()[39m

[31mKeyError[39m: Ellipsis

The above exception was the direct cause of the following exception:

[31mKeyError[39m                                  Traceback (most recent call last)
[36mCell[39m[36m [39m[32mIn[17][39m[32m, line 4[39m
[32m      1[39m [38;5;66;03m# Define your column name below[39;00m
[32m      2[39m column_name = ...
[32m----> [39m[32m4[39m [38;5;28mprint[39m([43mfull_dataframe[49m[43m[[49m[43mcolumn_name[49m[43m][49m.unique())

[36mFile [39m[32m/opt/miniconda3/envs/jb_py311/lib/python3.11/site-packages/pandas/core/frame.py:3807[39m, in [36mDataFrame.__getitem__[39m[34m(self, key)[39m
[32m   3805[39m [38;5;28;01mif[39;00m [38;5;28mself[39m.columns.nlevels > [32m1[39m:
[32m   3806[39m     [38;5;28;01mreturn[39;00m [38;5;28mself[39m._getitem_multilevel(key)
[32m-> [39m[32m3807[39m indexer = [38;5;28;43mself[39;49m[43m.[49m[43mcolumns[49m[43m.[49m[43mget_loc[49m[43m([49m[43mkey[49m[43m)[49m
[32m   3808[39m [38;5;28;01mif[39;00m is_integer(indexer):
[32m   3809[39m     indexer = [indexer]

[36mFile [39m[32m/opt/miniconda3/envs/jb_py311/lib/python3.11/site-packages/pandas/core/indexes/base.py:3804[39m, in [36mIndex.get_loc[39m[34m(self, key, method, tolerance)[39m
[32m   3802[39m     [38;5;28;01mreturn[39;00m [38;5;28mself[39m._engine.get_loc(casted_key)
[32m   3803[39m [38;5;28;01mexcept[39;00m [38;5;167;01mKeyError[39;00m [38;5;28;01mas[39;00m err:
[32m-> [39m[32m3804[39m     [38;5;28;01mraise[39;00m [38;5;167;01mKeyError[39;00m(key) [38;5;28;01mfrom[39;00m[38;5;250m [39m[34;01merr[39;00m
[32m   3805[39m [38;5;28;01mexcept[39;00m [38;5;167;01mTypeError[39;00m:
[32m   3806[39m     [38;5;66;03m# If we have a listlike key, _check_indexing_error will raise[39;00m
[32m   3807[39m     [38;5;66;03m#  InvalidIndexError. Otherwise we fall through and re-raise[39;00m
[32m   3808[39m     [38;5;66;03m#  the TypeError.[39;00m
[32m   3809[39m     [38;5;28mself[39m._check_indexing_error(key)

[31mKeyError[39m: Ellipsis

